Workbook

Sheet Cómo usar
B1: Qi Snacks · Calculadora de costos y precios
B2: Compras → Recetas → Producto terminado → Precio de venta
B4: Paso a paso
B5: 1. Insumos | C5: Lista de todo lo que comprás: ingredientes, bolsas, etiquetas y productos de reventa. Ya están cargados los ingredientes de la web. Para cada uno indicá la unidad base: g (sólidos), ml (líquidos) o unidad.
B6: 2. Compras | C6: Cada vez que comprás algo, agregá una fila: fecha, insumo, cantidad, unidad (kg, g, l, ml, unidad…) y precio total pagado. La planilla convierte todo y calcula el costo por gramo / ml / unidad.
B7: 3. Recetas | C7: Para cada receta, una fila por ingrediente con la cantidad que usás en UNA tanda. Ya están cargados los ingredientes de cada producto: solo falta completar las cantidades (columna amarilla).
B8: 4. Costo por Receta | C8: Pesá el producto terminado que sale de cada tanda (después del horno) y cargalo como rendimiento. Así se obtiene el costo real por gramo.
B9: 5. Precios | C9: Cada producto y presentación (individual / familiar). Elegís receta, gramos por paquete, envase y etiqueta. Te muestra el COSTO TOTAL, el PRECIO SUGERIDO y el margen real con el precio que cobrás hoy.
B10: 6. Combos | C10: Combo Degustación y Promo del Recreo: suma los costos de los productos que llevan, más extras (juguete, caja), y muestra el margen y el descuento frente a comprarlos sueltos.
B11: Configuración | C11: Margen deseado, % de gastos indirectos (gas, luz, tu tiempo), método de precio (último o promedio) y redondeo. Cambiar un valor actualiza todo.
B13: Colores
B14: Texto azul / fondo amarillo | C14: Celdas para completar o modificar.
B15: Texto negro / fondo gris | C15: Fórmulas: se calculan solas, no hace falta tocarlas.
B16: Texto verde | C16: Fórmula que trae un dato de otra hoja.
B17: Fondo naranja claro | C17: DATOS DE EJEMPLO (Galletas Marineras y sus compras). Reemplazalos por tus datos reales.
B19: Cómo se calcula
B20: Costo por gramo de insumo | C20: Precio total pagado ÷ cantidad comprada (pasada a g, ml o unidades).
B21: Costo de la receta | C21: Suma de (cantidad de cada ingrediente × su costo por gramo).
B22: Costo por gramo terminado | C22: Costo de la receta ÷ gramos de producto terminado que rinde la tanda.
B23: Costo del paquete | C23: Gramos del paquete × costo por gramo terminado + envase + etiqueta + % gastos indirectos.
B24: Precio sugerido | C24: Costo del paquete ÷ (1 − margen). Con 60% de margen, el precio es 2,5 veces el costo.
B26: Columnas Control / Estado | C26: Avisan qué falta ("Falta cantidad", "Insumo sin compras", "Falta rendimiento", "Unidad incompatible"…). Cuando todo dice OK, el costo de ese producto está completo.
B27: Agregar cosas nuevas | C27: Insumo nuevo → hoja Insumos. Receta nueva → nombre en Costo por Receta y sus ingredientes en Recetas. Producto o presentación nueva → hoja Precios. Escribilo en la primera fila vacía, sin dejar filas en blanco en el medio: así aparece solo en las listas desplegables.

Sheet Insumos
A1: Insumos: ingredientes, packaging y reventa
A2: Lista maestra. Cargá acá cada cosa que comprás (una sola vez). Los costos se calculan solos desde la hoja Compras.
A4: Insumo | B4: Tipo | C4: Unidad base | D4: Fecha última compra | E4: Costo último ($ por unidad base) | F4: Costo promedio ($ por unidad base) | G4: Costo que se usa ($ por unidad base) | H4: Costo por kg / litro / unidad | I4: Estado
A5: Aceite de oliva | B5: Ingrediente | C5: ml | D5: =IF(A5="","",IF(COUNTIFS(Compras!$B$5:$B$2000,A5,Compras!$H$5:$H$2000,">0")=0,"",_xlfn.MAXIFS(Compras!$A$5:$A$2000,Compras!$B$5:$B$2000,A5,Compras!$H$5:$H$2000,">0"))) -> 46280 | E5: =IF(D5="","",SUMIFS(Compras!$H$5:$H$2000,Compras!$B$5:$B$2000,A5,Compras!$A$5:$A$2000,D5,Compras!$H$5:$H$2000,">0")/COUNTIFS(Compras!$B$5:$B$2000,A5,Compras!$A$5:$A$2000,D5,Compras!$H$5:$H$2000,">0")) -> 18 | F5: =IF(D5="","",SUMIFS(Compras!$F$5:$F$2000,Compras!$B$5:$B$2000,A5,Compras!$H$5:$H$2000,">0")/SUMIFS(Compras!$G$5:$G$2000,Compras!$B$5:$B$2000,A5,Compras!$H$5:$H$2000,">0")) -> 17.25 | G5: =IF(D5="","",IF(CFG_Metodo="Promedio",F5,E5)) -> 18 | H5: =IF(G5="","",IF(C5="unidad",G5,G5*1000)) -> 18000 | I5: =IF(A5="","",IF(C5="","Falta unidad base",IF(D5="","Sin compras cargadas","OK"))) -> OK
A6: Ajo en polvo | B6: Ingrediente | C6: g | D6: =IF(A6="","",IF(COUNTIFS(Compras!$B$5:$B$2000,A6,Compras!$H$5:$H$2000,">0")=0,"",_xlfn.MAXIFS(Compras!$A$5:$A$2000,Compras!$B$5:$B$2000,A6,Compras!$H$5:$H$2000,">0"))) | E6: =IF(D6="","",SUMIFS(Compras!$H$5:$H$2000,Compras!$B$5:$B$2000,A6,Compras!$A$5:$A$2000,D6,Compras!$H$5:$H$2000,">0")/COUNTIFS(Compras!$B$5:$B$2000,A6,Compras!$A$5:$A$2000,D6,Compras!$H$5:$H$2000,">0")) | F6: =IF(D6="","",SUMIFS(Compras!$F$5:$F$2000,Compras!$B$5:$B$2000,A6,Compras!$H$5:$H$2000,">0")/SUMIFS(Compras!$G$5:$G$2000,Compras!$B$5:$B$2000,A6,Compras!$H$5:$H$2000,">0")) | G6: =IF(D6="","",IF(CFG_Metodo="Promedio",F6,E6)) | H6: =IF(G6="","",IF(C6="unidad",G6,G6*1000)) | I6: =IF(A6="","",IF(C6="","Falta unidad base",IF(D6="","Sin compras cargadas","OK"))) -> Sin compras cargadas
A7: Almidón de maíz | B7: Ingrediente | C7: g | D7: =IF(A7="","",IF(COUNTIFS(Compras!$B$5:$B$2000,A7,Compras!$H$5:$H$2000,">0")=0,"",_xlfn.MAXIFS(Compras!$A$5:$A$2000,Compras!$B$5:$B$2000,A7,Compras!$H$5:$H$2000,">0"))) -> 46267 | E7: =IF(D7="","",SUMIFS(Compras!$H$5:$H$2000,Compras!$B$5:$B$2000,A7,Compras!$A$5:$A$2000,D7,Compras!$H$5:$H$2000,">0")/COUNTIFS(Compras!$B$5:$B$2000,A7,Compras!$A$5:$A$2000,D7,Compras!$H$5:$H$2000,">0")) -> 3 | F7: =IF(D7="","",SUMIFS(Compras!$F$5:$F$2000,Compras!$B$5:$B$2000,A7,Compras!$H$5:$H$2000,">0")/SUMIFS(Compras!$G$5:$G$2000,Compras!$B$5:$B$2000,A7,Compras!$H$5:$H$2000,">0")) -> 3 | G7: =IF(D7="","",IF(CFG_Metodo="Promedio",F7,E7)) -> 3 | H7: =IF(G7="","",IF(C7="unidad",G7,G7*1000)) -> 3000 | I7: =IF(A7="","",IF(C7="","Falta unidad base",IF(D7="","Sin compras cargadas","OK"))) -> OK
A8: Almidón de mandioca | B8: Ingrediente | C8: g | D8: =IF(A8="","",IF(COUNTIFS(Compras!$B$5:$B$2000,A8,Compras!$H$5:$H$2000,">0")=0,"",_xlfn.MAXIFS(Compras!$A$5:$A$2000,Compras!$B$5:$B$2000,A8,Compras!$H$5:$H$2000,">0"))) -> 46267 | E8: =IF(D8="","",SUMIFS(Compras!$H$5:$H$2000,Compras!$B$5:$B$2000,A8,Compras!$A$5:$A$2000,D8,Compras!$H$5:$H$2000,">0")/COUNTIFS(Compras!$B$5:$B$2000,A8,Compras!$A$5:$A$2000,D8,Compras!$H$5:$H$2000,">0")) -> 3.5 | F8: =IF(D8="","",SUMIFS(Compras!$F$5:$F$2000,Compras!$B$5:$B$2000,A8,Compras!$H$5:$H$2000,">0")/SUMIFS(Compras!$G$5:$G$2000,Compras!$B$5:$B$2000,A8,Compras!$H$5:$H$2000,">0")) -> 3.5 | G8: =IF(D8="","",IF(CFG_Metodo="Promedio",F8,E8)) -> 3.5 | H8: =IF(G8="","",IF(C8="unidad",G8,G8*1000)) -> 3500 | I8: =IF(A8="","",IF(C8="","Falta unidad base",IF(D8="","Sin compras cargadas","OK"))) -> OK
A9: Azúcar de coco | B9: Ingrediente | C9: g | D9: =IF(A9="","",IF(COUNTIFS(Compras!$B$5:$B$2000,A9,Compras!$H$5:$H$2000,">0")=0,"",_xlfn.MAXIFS(Compras!$A$5:$A$2000,Compras!$B$5:$B$2000,A9,Compras!$H$5:$H$2000,">0"))) | E9: =IF(D9="","",SUMIFS(Compras!$H$5:$H$2000,Compras!$B$5:$B$2000,A9,Compras!$A$5:$A$2000,D9,Compras!$H$5:$H$2000,">0")/COUNTIFS(Compras!$B$5:$B$2000,A9,Compras!$A$5:$A$2000,D9,Compras!$H$5:$H$2000,">0")) | F9: =IF(D9="","",SUMIFS(Compras!$F$5:$F$2000,Compras!$B$5:$B$2000,A9,Compras!$H$5:$H$2000,">0")/SUMIFS(Compras!$G$5:$G$2000,Compras!$B$5:$B$2000,A9,Compras!$H$5:$H$2000,">0")) | G9: =IF(D9="","",IF(CFG_Metodo="Promedio",F9,E9)) | H9: =IF(G9="","",IF(C9="unidad",G9,G9*1000)) | I9: =IF(A9="","",IF(C9="","Falta unidad base",IF(D9="","Sin compras cargadas","OK"))) -> Sin compras cargadas
A10: Batata | B10: Ingrediente | C10: g | D10: =IF(A10="","",IF(COUNTIFS(Compras!$B$5:$B$2000,A10,Compras!$H$5:$H$2000,">0")=0,"",_xlfn.MAXIFS(Compras!$A$5:$A$2000,Compras!$B$5:$B$2000,A10,Compras!$H$5:$H$2000,">0"))) | E10: =IF(D10="","",SUMIFS(Compras!$H$5:$H$2000,Compras!$B$5:$B$2000,A10,Compras!$A$5:$A$2000,D10,Compras!$H$5:$H$2000,">0")/COUNTIFS(Compras!$B$5:$B$2000,A10,Compras!$A$5:$A$2000,D10,Compras!$H$5:$H$2000,">0")) | F10: =IF(D10="","",SUMIFS(Compras!$F$5:$F$2000,Compras!$B$5:$B$2000,A10,Compras!$H$5:$H$2000,">0")/SUMIFS(Compras!$G$5:$G$2000,Compras!$B$5:$B$2000,A10,Compras!$H$5:$H$2000,">0")) | G10: =IF(D10="","",IF(CFG_Metodo="Promedio",F10,E10)) | H10: =IF(G10="","",IF(C10="unidad",G10,G10*1000)) | I10: =IF(A10="","",IF(C10="","Falta unidad base",IF(D10="","Sin compras cargadas","OK"))) -> Sin compras cargadas
A11: Cebolla en polvo | B11: Ingrediente | C11: g | D11: =IF(A11="","",IF(COUNTIFS(Compras!$B$5:$B$2000,A11,Compras!$H$5:$H$2000,">0")=0,"",_xlfn.MAXIFS(Compras!$A$5:$A$2000,Compras!$B$5:$B$2000,A11,Compras!$H$5:$H$2000,">0"))) | E11: =IF(D11="","",SUMIFS(Compras!$H$5:$H$2000,Compras!$B$5:$B$2000,A11,Compras!$A$5:$A$2000,D11,Compras!$H$5:$H$2000,">0")/COUNTIFS(Compras!$B$5:$B$2000,A11,Compras!$A$5:$A$2000,D11,Compras!$H$5:$H$2000,">0")) | F11: =IF(D11="","",SUMIFS(Compras!$F$5:$F$2000,Compras!$B$5:$B$2000,A11,Compras!$H$5:$H$2000,">0")/SUMIFS(Compras!$G$5:$G$2000,Compras!$B$5:$B$2000,A11,Compras!$H$5:$H$2000,">0")) | G11: =IF(D11="","",IF(CFG_Metodo="Promedio",F11,E11)) | H11: =IF(G11="","",IF(C11="unidad",G11,G11*1000)) | I11: =IF(A11="","",IF(C11="","Falta unidad base",IF(D11="","Sin compras cargadas","OK"))) -> Sin compras cargadas
A12: Chocolate 70% sin azúcar | B12: Ingrediente | C12: g | D12: =IF(A12="","",IF(COUNTIFS(Compras!$B$5:$B$2000,A12,Compras!$H$5:$H$2000,">0")=0,"",_xlfn.MAXIFS(Compras!$A$5:$A$2000,Compras!$B$5:$B$2000,A12,Compras!$H$5:$H$2000,">0"))) | E12: =IF(D12="","",SUMIFS(Compras!$H$5:$H$2000,Compras!$B$5:$B$2000,A12,Compras!$A$5:$A$2000,D12,Compras!$H$5:$H$2000,">0")/COUNTIFS(Compras!$B$5:$B$2000,A12,Compras!$A$5:$A$2000,D12,Compras!$H$5:$H$2000,">0")) | F12: =IF(D12="","",SUMIFS(Compras!$F$5:$F$2000,Compras!$B$5:$B$2000,A12,Compras!$H$5:$H$2000,">0")/SUMIFS(Compras!$G$5:$G$2000,Compras!$B$5:$B$2000,A12,Compras!$H$5:$H$2000,">0")) | G12: =IF(D12="","",IF(CFG_Metodo="Promedio",F12,E12)) | H12: =IF(G12="","",IF(C12="unidad",G12,G12*1000)) | I12: =IF(A12="","",IF(C12="","Falta unidad base",IF(D12="","Sin compras cargadas","OK"))) -> Sin compras cargadas
A13: Cúrcuma | B13: Ingrediente | C13: g | D13: =IF(A13="","",IF(COUNTIFS(Compras!$B$5:$B$2000,A13,Compras!$H$5:$H$2000,">0")=0,"",_xlfn.MAXIFS(Compras!$A$5:$A$2000,Compras!$B$5:$B$2000,A13,Compras!$H$5:$H$2000,">0"))) | E13: =IF(D13="","",SUMIFS(Compras!$H$5:$H$2000,Compras!$B$5:$B$2000,A13,Compras!$A$5:$A$2000,D13,Compras!$H$5:$H$2000,">0")/COUNTIFS(Compras!$B$5:$B$2000,A13,Compras!$A$5:$A$2000,D13,Compras!$H$5:$H$2000,">0")) | F13: =IF(D13="","",SUMIFS(Compras!$F$5:$F$2000,Compras!$B$5:$B$2000,A13,Compras!$H$5:$H$2000,">0")/SUMIFS(Compras!$G$5:$G$2000,Compras!$B$5:$B$2000,A13,Compras!$H$5:$H$2000,">0")) | G13: =IF(D13="","",IF(CFG_Metodo="Promedio",F13,E13)) | H13: =IF(G13="","",IF(C13="unidad",G13,G13*1000)) | I13: =IF(A13="","",IF(C13="","Falta unidad base",IF(D13="","Sin compras cargadas","OK"))) -> Sin compras cargadas
A14: Extracto de vainilla | B14: Ingrediente | C14: ml | D14: =IF(A14="","",IF(COUNTIFS(Compras!$B$5:$B$2000,A14,Compras!$H$5:$H$2000,">0")=0,"",_xlfn.MAXIFS(Compras!$A$5:$A$2000,Compras!$B$5:$B$2000,A14,Compras!$H$5:$H$2000,">0"))) | E14: =IF(D14="","",SUMIFS(Compras!$H$5:$H$2000,Compras!$B$5:$B$2000,A14,Compras!$A$5:$A$2000,D14,Compras!$H$5:$H$2000,">0")/COUNTIFS(Compras!$B$5:$B$2000,A14,Compras!$A$5:$A$2000,D14,Compras!$H$5:$H$2000,">0")) | F14: =IF(D14="","",SUMIFS(Compras!$F$5:$F$2000,Compras!$B$5:$B$2000,A14,Compras!$H$5:$H$2000,">0")/SUMIFS(Compras!$G$5:$G$2000,Compras!$B$5:$B$2000,A14,Compras!$H$5:$H$2000,">0")) | G14: =IF(D14="","",IF(CFG_Metodo="Promedio",F14,E14)) | H14: =IF(G14="","",IF(C14="unidad",G14,G14*1000)) | I14: =IF(A14="","",IF(C14="","Falta unidad base",IF(D14="","Sin compras cargadas","OK"))) -> Sin compras cargadas
A15: Garbanzos | B15: Ingrediente | C15: g | D15: =IF(A15="","",IF(COUNTIFS(Compras!$B$5:$B$2000,A15,Compras!$H$5:$H$2000,">0")=0,"",_xlfn.MAXIFS(Compras!$A$5:$A$2000,Compras!$B$5:$B$2000,A15,Compras!$H$5:$H$2000,">0"))) | E15: =IF(D15="","",SUMIFS(Compras!$H$5:$H$2000,Compras!$B$5:$B$2000,A15,Compras!$A$5:$A$2000,D15,Compras!$H$5:$H$2000,">0")/COUNTIFS(Compras!$B$5:$B$2000,A15,Compras!$A$5:$A$2000,D15,Compras!$H$5:$H$2000,">0")) | F15: =IF(D15="","",SUMIFS(Compras!$F$5:$F$2000,Compras!$B$5:$B$2000,A15,Compras!$H$5:$H$2000,">0")/SUMIFS(Compras!$G$5:$G$2000,Compras!$B$5:$B$2000,A15,Compras!$H$5:$H$2000,">0")) | G15: =IF(D15="","",IF(CFG_Metodo="Promedio",F15,E15)) | H15: =IF(G15="","",IF(C15="unidad",G15,G15*1000)) | I15: =IF(A15="","",IF(C15="","Falta unidad base",IF(D15="","Sin compras cargadas","OK"))) -> Sin compras cargadas
A16: Goma xántica | B16: Ingrediente | C16: g | D16: =IF(A16="","",IF(COUNTIFS(Compras!$B$5:$B$2000,A16,Compras!$H$5:$H$2000,">0")=0,"",_xlfn.MAXIFS(Compras!$A$5:$A$2000,Compras!$B$5:$B$2000,A16,Compras!$H$5:$H$2000,">0"))) -> 46267 | E16: =IF(D16="","",SUMIFS(Compras!$H$5:$H$2000,Compras!$B$5:$B$2000,A16,Compras!$A$5:$A$2000,D16,Compras!$H$5:$H$2000,">0")/COUNTIFS(Compras!$B$5:$B$2000,A16,Compras!$A$5:$A$2000,D16,Compras!$H$5:$H$2000,">0")) -> 60 | F16: =IF(D16="","",SUMIFS(Compras!$F$5:$F$2000,Compras!$B$5:$B$2000,A16,Compras!$H$5:$H$2000,">0")/SUMIFS(Compras!$G$5:$G$2000,Compras!$B$5:$B$2000,A16,Compras!$H$5:$H$2000,">0")) -> 60 | G16: =IF(D16="","",IF(CFG_Metodo="Promedio",F16,E16)) -> 60 | H16: =IF(G16="","",IF(C16="unidad",G16,G16*1000)) -> 60000 | I16: =IF(A16="","",IF(C16="","Falta unidad base",IF(D16="","Sin compras cargadas","OK"))) -> OK
... A50: Berenjenas y Pera 200 g | B50: Reventa | C50: unidad | D50: =IF(A50="","",IF(COUNTIFS(Compras!$B$5:$B$2000,A50,Compras!$H$5:$H$2000,">0")=0,"",_xlfn.MAXIFS(Compras!$A$5:$A$2000,Compras!$B$5:$B$2000,A50,Compras!$H$5:$H$2000,">0"))) | E50: =IF(D50="","",SUMIFS(Compras!$H$5:$H$2000,Compras!$B$5:$B$2000,A50,Compras!$A$5:$A$2000,D50,Compras!$H$5:$H$2000,">0")/COUNTIFS(Compras!$B$5:$B$2000,A50,Compras!$A$5:$A$2000,D50,Compras!$H$5:$H$2000,">0")) | F50: =IF(D50="","",SUMIFS(Compras!$F$5:$F$2000,Compras!$B$5:$B$2000,A50,Compras!$H$5:$H$2000,">0")/SUMIFS(Compras!$G$5:$G$2000,Compras!$B$5:$B$2000,A50,Compras!$H$5:$H$2000,">0")) | G50: =IF(D50="","",IF(CFG_Metodo="Promedio",F50,E50)) | H50: =IF(G50="","",IF(C50="unidad",G50,G50*1000)) | I50: =IF(A50="","",IF(C50="","Falta unidad base",IF(D50="","Sin compras cargadas","OK"))) -> Sin compras cargadas
D51: =IF(A51="","",IF(COUNTIFS(Compras!$B$5:$B$2000,A51,Compras!$H$5:$H$2000,">0")=0,"",_xlfn.MAXIFS(Compras!$A$5:$A$2000,Compras!$B$5:$B$2000,A51,Compras!$H$5:$H$2000,">0"))) | E51: =IF(D51="","",SUMIFS(Compras!$H$5:$H$2000,Compras!$B$5:$B$2000,A51,Compras!$A$5:$A$2000,D51,Compras!$H$5:$H$2000,">0")/COUNTIFS(Compras!$B$5:$B$2000,A51,Compras!$A$5:$A$2000,D51,Compras!$H$5:$H$2000,">0")) | F51: =IF(D51="","",SUMIFS(Compras!$F$5:$F$2000,Compras!$B$5:$B$2000,A51,Compras!$H$5:$H$2000,">0")/SUMIFS(Compras!$G$5:$G$2000,Compras!$B$5:$B$2000,A51,Compras!$H$5:$H$2000,">0")) | G51: =IF(D51="","",IF(CFG_Metodo="Promedio",F51,E51)) | H51: =IF(G51="","",IF(C51="unidad",G51,G51*1000)) | I51: =IF(A51="","",IF(C51="","Falta unidad base",IF(D51="","Sin compras cargadas","OK")))
D52: =IF(A52="","",IF(COUNTIFS(Compras!$B$5:$B$2000,A52,Compras!$H$5:$H$2000,">0")=0,"",_xlfn.MAXIFS(Compras!$A$5:$A$2000,Compras!$B$5:$B$2000,A52,Compras!$H$5:$H$2000,">0"))) | E52: =IF(D52="","",SUMIFS(Compras!$H$5:$H$2000,Compras!$B$5:$B$2000,A52,Compras!$A$5:$A$2000,D52,Compras!$H$5:$H$2000,">0")/COUNTIFS(Compras!$B$5:$B$2000,A52,Compras!$A$5:$A$2000,D52,Compras!$H$5:$H$2000,">0")) | F52: =IF(D52="","",SUMIFS(Compras!$F$5:$F$2000,Compras!$B$5:$B$2000,A52,Compras!$H$5:$H$2000,">0")/SUMIFS(Compras!$G$5:$G$2000,Compras!$B$5:$B$2000,A52,Compras!$H$5:$H$2000,">0")) | G52: =IF(D52="","",IF(CFG_Metodo="Promedio",F52,E52)) | H52: =IF(G52="","",IF(C52="unidad",G52,G52*1000)) | I52: =IF(A52="","",IF(C52="","Falta unidad base",IF(D52="","Sin compras cargadas","OK")))
D53: =IF(A53="","",IF(COUNTIFS(Compras!$B$5:$B$2000,A53,Compras!$H$5:$H$2000,">0")=0,"",_xlfn.MAXIFS(Compras!$A$5:$A$2000,Compras!$B$5:$B$2000,A53,Compras!$H$5:$H$2000,">0"))) | E53: =IF(D53="","",SUMIFS(Compras!$H$5:$H$2000,Compras!$B$5:$B$2000,A53,Compras!$A$5:$A$2000,D53,Compras!$H$5:$H$2000,">0")/COUNTIFS(Compras!$B$5:$B$2000,A53,Compras!$A$5:$A$2000,D53,Compras!$H$5:$H$2000,">0")) | F53: =IF(D53="","",SUMIFS(Compras!$F$5:$F$2000,Compras!$B$5:$B$2000,A53,Compras!$H$5:$H$2000,">0")/SUMIFS(Compras!$G$5:$G$2000,Compras!$B$5:$B$2000,A53,Compras!$H$5:$H$2000,">0")) | G53: =IF(D53="","",IF(CFG_Metodo="Promedio",F53,E53)) | H53: =IF(G53="","",IF(C53="unidad",G53,G53*1000)) | I53: =IF(A53="","",IF(C53="","Falta unidad base",IF(D53="","Sin compras cargadas","OK")))
D54: =IF(A54="","",IF(COUNTIFS(Compras!$B$5:$B$2000,A54,Compras!$H$5:$H$2000,">0")=0,"",_xlfn.MAXIFS(Compras!$A$5:$A$2000,Compras!$B$5:$B$2000,A54,Compras!$H$5:$H$2000,">0"))) | E54: =IF(D54="","",SUMIFS(Compras!$H$5:$H$2000,Compras!$B$5:$B$2000,A54,Compras!$A$5:$A$2000,D54,Compras!$H$5:$H$2000,">0")/COUNTIFS(Compras!$B$5:$B$2000,A54,Compras!$A$5:$A$2000,D54,Compras!$H$5:$H$2000,">0")) | F54: =IF(D54="","",SUMIFS(Compras!$F$5:$F$2000,Compras!$B$5:$B$2000,A54,Compras!$H$5:$H$2000,">0")/SUMIFS(Compras!$G$5:$G$2000,Compras!$B$5:$B$2000,A54,Compras!$H$5:$H$2000,">0")) | G54: =IF(D54="","",IF(CFG_Metodo="Promedio",F54,E54)) | H54: =IF(G54="","",IF(C54="unidad",G54,G54*1000)) | I54: =IF(A54="","",IF(C54="","Falta unidad base",IF(D54="","Sin compras cargadas","OK")))
D55: =IF(A55="","",IF(COUNTIFS(Compras!$B$5:$B$2000,A55,Compras!$H$5:$H$2000,">0")=0,"",_xlfn.MAXIFS(Compras!$A$5:$A$2000,Compras!$B$5:$B$2000,A55,Compras!$H$5:$H$2000,">0"))) | E55: =IF(D55="","",SUMIFS(Compras!$H$5:$H$2000,Compras!$B$5:$B$2000,A55,Compras!$A$5:$A$2000,D55,Compras!$H$5:$H$2000,">0")/COUNTIFS(Compras!$B$5:$B$2000,A55,Compras!$A$5:$A$2000,D55,Compras!$H$5:$H$2000,">0")) | F55: =IF(D55="","",SUMIFS(Compras!$F$5:$F$2000,Compras!$B$5:$B$2000,A55,Compras!$H$5:$H$2000,">0")/SUMIFS(Compras!$G$5:$G$2000,Compras!$B$5:$B$2000,A55,Compras!$H$5:$H$2000,">0")) | G55: =IF(D55="","",IF(CFG_Metodo="Promedio",F55,E55)) | H55: =IF(G55="","",IF(C55="unidad",G55,G55*1000)) | I55: =IF(A55="","",IF(C55="","Falta unidad base",IF(D55="","Sin compras cargadas","OK")))
D56: =IF(A56="","",IF(COUNTIFS(Compras!$B$5:$B$2000,A56,Compras!$H$5:$H$2000,">0")=0,"",_xlfn.MAXIFS(Compras!$A$5:$A$2000,Compras!$B$5:$B$2000,A56,Compras!$H$5:$H$2000,">0"))) | E56: =IF(D56="","",SUMIFS(Compras!$H$5:$H$2000,Compras!$B$5:$B$2000,A56,Compras!$A$5:$A$2000,D56,Compras!$H$5:$H$2000,">0")/COUNTIFS(Compras!$B$5:$B$2000,A56,Compras!$A$5:$A$2000,D56,Compras!$H$5:$H$2000,">0")) | F56: =IF(D56="","",SUMIFS(Compras!$F$5:$F$2000,Compras!$B$5:$B$2000,A56,Compras!$H$5:$H$2000,">0")/SUMIFS(Compras!$G$5:$G$2000,Compras!$B$5:$B$2000,A56,Compras!$H$5:$H$2000,">0")) | G56: =IF(D56="","",IF(CFG_Metodo="Promedio",F56,E56)) | H56: =IF(G56="","",IF(C56="unidad",G56,G56*1000)) | I56: =IF(A56="","",IF(C56="","Falta unidad base",IF(D56="","Sin compras cargadas","OK")))
D57: =IF(A57="","",IF(COUNTIFS(Compras!$B$5:$B$2000,A57,Compras!$H$5:$H$2000,">0")=0,"",_xlfn.MAXIFS(Compras!$A$5:$A$2000,Compras!$B$5:$B$2000,A57,Compras!$H$5:$H$2000,">0"))) | E57: =IF(D57="","",SUMIFS(Compras!$H$5:$H$2000,Compras!$B$5:$B$2000,A57,Compras!$A$5:$A$2000,D57,Compras!$H$5:$H$2000,">0")/COUNTIFS(Compras!$B$5:$B$2000,A57,Compras!$A$5:$A$2000,D57,Compras!$H$5:$H$2000,">0")) | F57: =IF(D57="","",SUMIFS(Compras!$F$5:$F$2000,Compras!$B$5:$B$2000,A57,Compras!$H$5:$H$2000,">0")/SUMIFS(Compras!$G$5:$G$2000,Compras!$B$5:$B$2000,A57,Compras!$H$5:$H$2000,">0")) | G57: =IF(D57="","",IF(CFG_Metodo="Promedio",F57,E57)) | H57: =IF(G57="","",IF(C57="unidad",G57,G57*1000)) | I57: =IF(A57="","",IF(C57="","Falta unidad base",IF(D57="","Sin compras cargadas","OK")))
D58: =IF(A58="","",IF(COUNTIFS(Compras!$B$5:$B$2000,A58,Compras!$H$5:$H$2000,">0")=0,"",_xlfn.MAXIFS(Compras!$A$5:$A$2000,Compras!$B$5:$B$2000,A58,Compras!$H$5:$H$2000,">0"))) | E58: =IF(D58="","",SUMIFS(Compras!$H$5:$H$2000,Compras!$B$5:$B$2000,A58,Compras!$A$5:$A$2000,D58,Compras!$H$5:$H$2000,">0")/COUNTIFS(Compras!$B$5:$B$2000,A58,Compras!$A$5:$A$2000,D58,Compras!$H$5:$H$2000,">0")) | F58: =IF(D58="","",SUMIFS(Compras!$F$5:$F$2000,Compras!$B$5:$B$2000,A58,Compras!$H$5:$H$2000,">0")/SUMIFS(Compras!$G$5:$G$2000,Compras!$B$5:$B$2000,A58,Compras!$H$5:$H$2000,">0")) | G58: =IF(D58="","",IF(CFG_Metodo="Promedio",F58,E58)) | H58: =IF(G58="","",IF(C58="unidad",G58,G58*1000)) | I58: =IF(A58="","",IF(C58="","Falta unidad base",IF(D58="","Sin compras cargadas","OK")))
D59: =IF(A59="","",IF(COUNTIFS(Compras!$B$5:$B$2000,A59,Compras!$H$5:$H$2000,">0")=0,"",_xlfn.MAXIFS(Compras!$A$5:$A$2000,Compras!$B$5:$B$2000,A59,Compras!$H$5:$H$2000,">0"))) | E59: =IF(D59="","",SUMIFS(Compras!$H$5:$H$2000,Compras!$B$5:$B$2000,A59,Compras!$A$5:$A$2000,D59,Compras!$H$5:$H$2000,">0")/COUNTIFS(Compras!$B$5:$B$2000,A59,Compras!$A$5:$A$2000,D59,Compras!$H$5:$H$2000,">0")) | F59: =IF(D59="","",SUMIFS(Compras!$F$5:$F$2000,Compras!$B$5:$B$2000,A59,Compras!$H$5:$H$2000,">0")/SUMIFS(Compras!$G$5:$G$2000,Compras!$B$5:$B$2000,A59,Compras!$H$5:$H$2000,">0")) | G59: =IF(D59="","",IF(CFG_Metodo="Promedio",F59,E59)) | H59: =IF(G59="","",IF(C59="unidad",G59,G59*1000)) | I59: =IF(A59="","",IF(C59="","Falta unidad base",IF(D59="","Sin compras cargadas","OK")))
D60: =IF(A60="","",IF(COUNTIFS(Compras!$B$5:$B$2000,A60,Compras!$H$5:$H$2000,">0")=0,"",_xlfn.MAXIFS(Compras!$A$5:$A$2000,Compras!$B$5:$B$2000,A60,Compras!$H$5:$H$2000,">0"))) | E60: =IF(D60="","",SUMIFS(Compras!$H$5:$H$2000,Compras!$B$5:$B$2000,A60,Compras!$A$5:$A$2000,D60,Compras!$H$5:$H$2000,">0")/COUNTIFS(Compras!$B$5:$B$2000,A60,Compras!$A$5:$A$2000,D60,Compras!$H$5:$H$2000,">0")) | F60: =IF(D60="","",SUMIFS(Compras!$F$5:$F$2000,Compras!$B$5:$B$2000,A60,Compras!$H$5:$H$2000,">0")/SUMIFS(Compras!$G$5:$G$2000,Compras!$B$5:$B$2000,A60,Compras!$H$5:$H$2000,">0")) | G60: =IF(D60="","",IF(CFG_Metodo="Promedio",F60,E60)) | H60: =IF(G60="","",IF(C60="unidad",G60,G60*1000)) | I60: =IF(A60="","",IF(C60="","Falta unidad base",IF(D60="","Sin compras cargadas","OK")))
D61: =IF(A61="","",IF(COUNTIFS(Compras!$B$5:$B$2000,A61,Compras!$H$5:$H$2000,">0")=0,"",_xlfn.MAXIFS(Compras!$A$5:$A$2000,Compras!$B$5:$B$2000,A61,Compras!$H$5:$H$2000,">0"))) | E61: =IF(D61="","",SUMIFS(Compras!$H$5:$H$2000,Compras!$B$5:$B$2000,A61,Compras!$A$5:$A$2000,D61,Compras!$H$5:$H$2000,">0")/COUNTIFS(Compras!$B$5:$B$2000,A61,Compras!$A$5:$A$2000,D61,Compras!$H$5:$H$2000,">0")) | F61: =IF(D61="","",SUMIFS(Compras!$F$5:$F$2000,Compras!$B$5:$B$2000,A61,Compras!$H$5:$H$2000,">0")/SUMIFS(Compras!$G$5:$G$2000,Compras!$B$5:$B$2000,A61,Compras!$H$5:$H$2000,">0")) | G61: =IF(D61="","",IF(CFG_Metodo="Promedio",F61,E61)) | H61: =IF(G61="","",IF(C61="unidad",G61,G61*1000)) | I61: =IF(A61="","",IF(C61="","Falta unidad base",IF(D61="","Sin compras cargadas","OK")))
D62: =IF(A62="","",IF(COUNTIFS(Compras!$B$5:$B$2000,A62,Compras!$H$5:$H$2000,">0")=0,"",_xlfn.MAXIFS(Compras!$A$5:$A$2000,Compras!$B$5:$B$2000,A62,Compras!$H$5:$H$2000,">0"))) | E62: =IF(D62="","",SUMIFS(Compras!$H$5:$H$2000,Compras!$B$5:$B$2000,A62,Compras!$A$5:$A$2000,D62,Compras!$H$5:$H$2000,">0")/COUNTIFS(Compras!$B$5:$B$2000,A62,Compras!$A$5:$A$2000,D62,Compras!$H$5:$H$2000,">0")) | F62: =IF(D62="","",SUMIFS(Compras!$F$5:$F$2000,Compras!$B$5:$B$2000,A62,Compras!$H$5:$H$2000,">0")/SUMIFS(Compras!$G$5:$G$2000,Compras!$B$5:$B$2000,A62,Compras!$H$5:$H$2000,">0")) | G62: =IF(D62="","",IF(CFG_Metodo="Promedio",F62,E62)) | H62: =IF(G62="","",IF(C62="unidad",G62,G62*1000)) | I62: =IF(A62="","",IF(C62="","Falta unidad base",IF(D62="","Sin compras cargadas","OK")))
... D250: =IF(A250="","",IF(COUNTIFS(Compras!$B$5:$B$2000,A250,Compras!$H$5:$H$2000,">0")=0,"",_xlfn.MAXIFS(Compras!$A$5:$A$2000,Compras!$B$5:$B$2000,A250,Compras!$H$5:$H$2000,">0"))) | E250: =IF(D250="","",SUMIFS(Compras!$H$5:$H$2000,Compras!$B$5:$B$2000,A250,Compras!$A$5:$A$2000,D250,Compras!$H$5:$H$2000,">0")/COUNTIFS(Compras!$B$5:$B$2000,A250,Compras!$A$5:$A$2000,D250,Compras!$H$5:$H$2000,">0")) | F250: =IF(D250="","",SUMIFS(Compras!$F$5:$F$2000,Compras!$B$5:$B$2000,A250,Compras!$H$5:$H$2000,">0")/SUMIFS(Compras!$G$5:$G$2000,Compras!$B$5:$B$2000,A250,Compras!$H$5:$H$2000,">0")) | G250: =IF(D250="","",IF(CFG_Metodo="Promedio",F250,E250)) | H250: =IF(G250="","",IF(C250="unidad",G250,G250*1000)) | I250: =IF(A250="","",IF(C250="","Falta unidad base",IF(D250="","Sin compras cargadas","OK")))

Sheet Compras
A1: Compras de insumos
A2: Una fila por compra. Anotá la cantidad tal como la comprás (ej.: 1 kg, 500 g, 1 l, 100 unidades) y el precio total pagado.
A4: Fecha | B4: Insumo | C4: Proveedor | D4: Cantidad comprada | E4: Unidad | F4: Precio total pagado ($) | G4: Cantidad en unidad base | H4: Costo por unidad base ($) | I4: Control | J4: Notas
A5: 46267 | B5: Almidón de maíz | C5: Dietética (ejemplo) | D5: 1 | E5: kg | F5: 3000 | G5: =IF(OR(D5="",E5=""),"",IFERROR(D5*INDEX(UnidadesFactor,MATCH(E5,Unidades,0)),"")) -> 1000 | H5: =IF(I5<>"OK","",IF(G5=0,"",F5/G5)) -> 3 | I5: =IF(B5="","",IF(ISNA(MATCH(B5,ListaInsumos,0)),"Insumo no está en Insumos",IF(OR(D5="",E5="",F5=""),"Faltan datos",IF(INDEX(UnidadesBase,MATCH(E5,Unidades,0))<>INDEX(InsBase,MATCH(B5,ListaInsumos,0)),"Unidad incompatible",IF(A5="","Falta fecha","OK"))))) -> OK | J5: EJEMPLO: reemplazar por datos reales
A6: 46267 | B6: Harina de arroz | C6: Dietética (ejemplo) | D6: 1 | E6: kg | F6: 2800 | G6: =IF(OR(D6="",E6=""),"",IFERROR(D6*INDEX(UnidadesFactor,MATCH(E6,Unidades,0)),"")) -> 1000 | H6: =IF(I6<>"OK","",IF(G6=0,"",F6/G6)) -> 2.8 | I6: =IF(B6="","",IF(ISNA(MATCH(B6,ListaInsumos,0)),"Insumo no está en Insumos",IF(OR(D6="",E6="",F6=""),"Faltan datos",IF(INDEX(UnidadesBase,MATCH(E6,Unidades,0))<>INDEX(InsBase,MATCH(B6,ListaInsumos,0)),"Unidad incompatible",IF(A6="","Falta fecha","OK"))))) -> OK | J6: EJEMPLO: reemplazar por datos reales
A7: 46267 | B7: Almidón de mandioca | C7: Dietética (ejemplo) | D7: 1 | E7: kg | F7: 3500 | G7: =IF(OR(D7="",E7=""),"",IFERROR(D7*INDEX(UnidadesFactor,MATCH(E7,Unidades,0)),"")) -> 1000 | H7: =IF(I7<>"OK","",IF(G7=0,"",F7/G7)) -> 3.5 | I7: =IF(B7="","",IF(ISNA(MATCH(B7,ListaInsumos,0)),"Insumo no está en Insumos",IF(OR(D7="",E7="",F7=""),"Faltan datos",IF(INDEX(UnidadesBase,MATCH(E7,Unidades,0))<>INDEX(InsBase,MATCH(B7,ListaInsumos,0)),"Unidad incompatible",IF(A7="","Falta fecha","OK"))))) -> OK | J7: EJEMPLO: reemplazar por datos reales
A8: 46254 | B8: Aceite de oliva | C8: Mayorista (ejemplo) | D8: 1 | E8: l | F8: 16500 | G8: =IF(OR(D8="",E8=""),"",IFERROR(D8*INDEX(UnidadesFactor,MATCH(E8,Unidades,0)),"")) -> 1000 | H8: =IF(I8<>"OK","",IF(G8=0,"",F8/G8)) -> 16.5 | I8: =IF(B8="","",IF(ISNA(MATCH(B8,ListaInsumos,0)),"Insumo no está en Insumos",IF(OR(D8="",E8="",F8=""),"Faltan datos",IF(INDEX(UnidadesBase,MATCH(E8,Unidades,0))<>INDEX(InsBase,MATCH(B8,ListaInsumos,0)),"Unidad incompatible",IF(A8="","Falta fecha","OK"))))) -> OK | J8: EJEMPLO: reemplazar por datos reales
A9: 46280 | B9: Aceite de oliva | C9: Mayorista (ejemplo) | D9: 1 | E9: l | F9: 18000 | G9: =IF(OR(D9="",E9=""),"",IFERROR(D9*INDEX(UnidadesFactor,MATCH(E9,Unidades,0)),"")) -> 1000 | H9: =IF(I9<>"OK","",IF(G9=0,"",F9/G9)) -> 18 | I9: =IF(B9="","",IF(ISNA(MATCH(B9,ListaInsumos,0)),"Insumo no está en Insumos",IF(OR(D9="",E9="",F9=""),"Faltan datos",IF(INDEX(UnidadesBase,MATCH(E9,Unidades,0))<>INDEX(InsBase,MATCH(B9,ListaInsumos,0)),"Unidad incompatible",IF(A9="","Falta fecha","OK"))))) -> OK | J9: EJEMPLO: reemplazar por datos reales
A10: 46267 | B10: Sal marina | C10: Dietética (ejemplo) | D10: 500 | E10: g | F10: 2500 | G10: =IF(OR(D10="",E10=""),"",IFERROR(D10*INDEX(UnidadesFactor,MATCH(E10,Unidades,0)),"")) -> 500 | H10: =IF(I10<>"OK","",IF(G10=0,"",F10/G10)) -> 5 | I10: =IF(B10="","",IF(ISNA(MATCH(B10,ListaInsumos,0)),"Insumo no está en Insumos",IF(OR(D10="",E10="",F10=""),"Faltan datos",IF(INDEX(UnidadesBase,MATCH(E10,Unidades,0))<>INDEX(InsBase,MATCH(B10,ListaInsumos,0)),"Unidad incompatible",IF(A10="","Falta fecha","OK"))))) -> OK | J10: EJEMPLO: reemplazar por datos reales
A11: 46267 | B11: Goma xántica | C11: Dietética (ejemplo) | D11: 100 | E11: g | F11: 6000 | G11: =IF(OR(D11="",E11=""),"",IFERROR(D11*INDEX(UnidadesFactor,MATCH(E11,Unidades,0)),"")) -> 100 | H11: =IF(I11<>"OK","",IF(G11=0,"",F11/G11)) -> 60 | I11: =IF(B11="","",IF(ISNA(MATCH(B11,ListaInsumos,0)),"Insumo no está en Insumos",IF(OR(D11="",E11="",F11=""),"Faltan datos",IF(INDEX(UnidadesBase,MATCH(E11,Unidades,0))<>INDEX(InsBase,MATCH(B11,ListaInsumos,0)),"Unidad incompatible",IF(A11="","Falta fecha","OK"))))) -> OK | J11: EJEMPLO: reemplazar por datos reales
A12: 46267 | B12: Polvo leudante | C12: Dietética (ejemplo) | D12: 100 | E12: g | F12: 1500 | G12: =IF(OR(D12="",E12=""),"",IFERROR(D12*INDEX(UnidadesFactor,MATCH(E12,Unidades,0)),"")) -> 100 | H12: =IF(I12<>"OK","",IF(G12=0,"",F12/G12)) -> 15 | I12: =IF(B12="","",IF(ISNA(MATCH(B12,ListaInsumos,0)),"Insumo no está en Insumos",IF(OR(D12="",E12="",F12=""),"Faltan datos",IF(INDEX(UnidadesBase,MATCH(E12,Unidades,0))<>INDEX(InsBase,MATCH(B12,ListaInsumos,0)),"Unidad incompatible",IF(A12="","Falta fecha","OK"))))) -> OK | J12: EJEMPLO: reemplazar por datos reales
A13: 46270 | B13: Bolsa individual | C13: Packaging (ejemplo) | D13: 100 | E13: unidad | F13: 8000 | G13: =IF(OR(D13="",E13=""),"",IFERROR(D13*INDEX(UnidadesFactor,MATCH(E13,Unidades,0)),"")) -> 100 | H13: =IF(I13<>"OK","",IF(G13=0,"",F13/G13)) -> 80 | I13: =IF(B13="","",IF(ISNA(MATCH(B13,ListaInsumos,0)),"Insumo no está en Insumos",IF(OR(D13="",E13="",F13=""),"Faltan datos",IF(INDEX(UnidadesBase,MATCH(E13,Unidades,0))<>INDEX(InsBase,MATCH(B13,ListaInsumos,0)),"Unidad incompatible",IF(A13="","Falta fecha","OK"))))) -> OK | J13: EJEMPLO: reemplazar por datos reales
A14: 46270 | B14: Bolsa familiar | C14: Packaging (ejemplo) | D14: 100 | E14: unidad | F14: 12000 | G14: =IF(OR(D14="",E14=""),"",IFERROR(D14*INDEX(UnidadesFactor,MATCH(E14,Unidades,0)),"")) -> 100 | H14: =IF(I14<>"OK","",IF(G14=0,"",F14/G14)) -> 120 | I14: =IF(B14="","",IF(ISNA(MATCH(B14,ListaInsumos,0)),"Insumo no está en Insumos",IF(OR(D14="",E14="",F14=""),"Faltan datos",IF(INDEX(UnidadesBase,MATCH(E14,Unidades,0))<>INDEX(InsBase,MATCH(B14,ListaInsumos,0)),"Unidad incompatible",IF(A14="","Falta fecha","OK"))))) -> OK | J14: EJEMPLO: reemplazar por datos reales
A15: 46270 | B15: Etiqueta | C15: Imprenta (ejemplo) | D15: 100 | E15: unidad | F15: 5000 | G15: =IF(OR(D15="",E15=""),"",IFERROR(D15*INDEX(UnidadesFactor,MATCH(E15,Unidades,0)),"")) -> 100 | H15: =IF(I15<>"OK","",IF(G15=0,"",F15/G15)) -> 50 | I15: =IF(B15="","",IF(ISNA(MATCH(B15,ListaInsumos,0)),"Insumo no está en Insumos",IF(OR(D15="",E15="",F15=""),"Faltan datos",IF(INDEX(UnidadesBase,MATCH(E15,Unidades,0))<>INDEX(InsBase,MATCH(B15,ListaInsumos,0)),"Unidad incompatible",IF(A15="","Falta fecha","OK"))))) -> OK | J15: EJEMPLO: reemplazar por datos reales
G16: =IF(OR(D16="",E16=""),"",IFERROR(D16*INDEX(UnidadesFactor,MATCH(E16,Unidades,0)),"")) | H16: =IF(I16<>"OK","",IF(G16=0,"",F16/G16)) | I16: =IF(B16="","",IF(ISNA(MATCH(B16,ListaInsumos,0)),"Insumo no está en Insumos",IF(OR(D16="",E16="",F16=""),"Faltan datos",IF(INDEX(UnidadesBase,MATCH(E16,Unidades,0))<>INDEX(InsBase,MATCH(B16,ListaInsumos,0)),"Unidad incompatible",IF(A16="","Falta fecha","OK")))))
G17: =IF(OR(D17="",E17=""),"",IFERROR(D17*INDEX(UnidadesFactor,MATCH(E17,Unidades,0)),"")) | H17: =IF(I17<>"OK","",IF(G17=0,"",F17/G17)) | I17: =IF(B17="","",IF(ISNA(MATCH(B17,ListaInsumos,0)),"Insumo no está en Insumos",IF(OR(D17="",E17="",F17=""),"Faltan datos",IF(INDEX(UnidadesBase,MATCH(E17,Unidades,0))<>INDEX(InsBase,MATCH(B17,ListaInsumos,0)),"Unidad incompatible",IF(A17="","Falta fecha","OK")))))
G18: =IF(OR(D18="",E18=""),"",IFERROR(D18*INDEX(UnidadesFactor,MATCH(E18,Unidades,0)),"")) | H18: =IF(I18<>"OK","",IF(G18=0,"",F18/G18)) | I18: =IF(B18="","",IF(ISNA(MATCH(B18,ListaInsumos,0)),"Insumo no está en Insumos",IF(OR(D18="",E18="",F18=""),"Faltan datos",IF(INDEX(UnidadesBase,MATCH(E18,Unidades,0))<>INDEX(InsBase,MATCH(B18,ListaInsumos,0)),"Unidad incompatible",IF(A18="","Falta fecha","OK")))))
G19: =IF(OR(D19="",E19=""),"",IFERROR(D19*INDEX(UnidadesFactor,MATCH(E19,Unidades,0)),"")) | H19: =IF(I19<>"OK","",IF(G19=0,"",F19/G19)) | I19: =IF(B19="","",IF(ISNA(MATCH(B19,ListaInsumos,0)),"Insumo no está en Insumos",IF(OR(D19="",E19="",F19=""),"Faltan datos",IF(INDEX(UnidadesBase,MATCH(E19,Unidades,0))<>INDEX(InsBase,MATCH(B19,ListaInsumos,0)),"Unidad incompatible",IF(A19="","Falta fecha","OK")))))
G20: =IF(OR(D20="",E20=""),"",IFERROR(D20*INDEX(UnidadesFactor,MATCH(E20,Unidades,0)),"")) | H20: =IF(I20<>"OK","",IF(G20=0,"",F20/G20)) | I20: =IF(B20="","",IF(ISNA(MATCH(B20,ListaInsumos,0)),"Insumo no está en Insumos",IF(OR(D20="",E20="",F20=""),"Faltan datos",IF(INDEX(UnidadesBase,MATCH(E20,Unidades,0))<>INDEX(InsBase,MATCH(B20,ListaInsumos,0)),"Unidad incompatible",IF(A20="","Falta fecha","OK")))))
G21: =IF(OR(D21="",E21=""),"",IFERROR(D21*INDEX(UnidadesFactor,MATCH(E21,Unidades,0)),"")) | H21: =IF(I21<>"OK","",IF(G21=0,"",F21/G21)) | I21: =IF(B21="","",IF(ISNA(MATCH(B21,ListaInsumos,0)),"Insumo no está en Insumos",IF(OR(D21="",E21="",F21=""),"Faltan datos",IF(INDEX(UnidadesBase,MATCH(E21,Unidades,0))<>INDEX(InsBase,MATCH(B21,ListaInsumos,0)),"Unidad incompatible",IF(A21="","Falta fecha","OK")))))
G22: =IF(OR(D22="",E22=""),"",IFERROR(D22*INDEX(UnidadesFactor,MATCH(E22,Unidades,0)),"")) | H22: =IF(I22<>"OK","",IF(G22=0,"",F22/G22)) | I22: =IF(B22="","",IF(ISNA(MATCH(B22,ListaInsumos,0)),"Insumo no está en Insumos",IF(OR(D22="",E22="",F22=""),"Faltan datos",IF(INDEX(UnidadesBase,MATCH(E22,Unidades,0))<>INDEX(InsBase,MATCH(B22,ListaInsumos,0)),"Unidad incompatible",IF(A22="","Falta fecha","OK")))))
G23: =IF(OR(D23="",E23=""),"",IFERROR(D23*INDEX(UnidadesFactor,MATCH(E23,Unidades,0)),"")) | H23: =IF(I23<>"OK","",IF(G23=0,"",F23/G23)) | I23: =IF(B23="","",IF(ISNA(MATCH(B23,ListaInsumos,0)),"Insumo no está en Insumos",IF(OR(D23="",E23="",F23=""),"Faltan datos",IF(INDEX(UnidadesBase,MATCH(E23,Unidades,0))<>INDEX(InsBase,MATCH(B23,ListaInsumos,0)),"Unidad incompatible",IF(A23="","Falta fecha","OK")))))
G24: =IF(OR(D24="",E24=""),"",IFERROR(D24*INDEX(UnidadesFactor,MATCH(E24,Unidades,0)),"")) | H24: =IF(I24<>"OK","",IF(G24=0,"",F24/G24)) | I24: =IF(B24="","",IF(ISNA(MATCH(B24,ListaInsumos,0)),"Insumo no está en Insumos",IF(OR(D24="",E24="",F24=""),"Faltan datos",IF(INDEX(UnidadesBase,MATCH(E24,Unidades,0))<>INDEX(InsBase,MATCH(B24,ListaInsumos,0)),"Unidad incompatible",IF(A24="","Falta fecha","OK")))))
G25: =IF(OR(D25="",E25=""),"",IFERROR(D25*INDEX(UnidadesFactor,MATCH(E25,Unidades,0)),"")) | H25: =IF(I25<>"OK","",IF(G25=0,"",F25/G25)) | I25: =IF(B25="","",IF(ISNA(MATCH(B25,ListaInsumos,0)),"Insumo no está en Insumos",IF(OR(D25="",E25="",F25=""),"Faltan datos",IF(INDEX(UnidadesBase,MATCH(E25,Unidades,0))<>INDEX(InsBase,MATCH(B25,ListaInsumos,0)),"Unidad incompatible",IF(A25="","Falta fecha","OK")))))
G26: =IF(OR(D26="",E26=""),"",IFERROR(D26*INDEX(UnidadesFactor,MATCH(E26,Unidades,0)),"")) | H26: =IF(I26<>"OK","",IF(G26=0,"",F26/G26)) | I26: =IF(B26="","",IF(ISNA(MATCH(B26,ListaInsumos,0)),"Insumo no está en Insumos",IF(OR(D26="",E26="",F26=""),"Faltan datos",IF(INDEX(UnidadesBase,MATCH(E26,Unidades,0))<>INDEX(InsBase,MATCH(B26,ListaInsumos,0)),"Unidad incompatible",IF(A26="","Falta fecha","OK")))))
G27: =IF(OR(D27="",E27=""),"",IFERROR(D27*INDEX(UnidadesFactor,MATCH(E27,Unidades,0)),"")) | H27: =IF(I27<>"OK","",IF(G27=0,"",F27/G27)) | I27: =IF(B27="","",IF(ISNA(MATCH(B27,ListaInsumos,0)),"Insumo no está en Insumos",IF(OR(D27="",E27="",F27=""),"Faltan datos",IF(INDEX(UnidadesBase,MATCH(E27,Unidades,0))<>INDEX(InsBase,MATCH(B27,ListaInsumos,0)),"Unidad incompatible",IF(A27="","Falta fecha","OK")))))
... G2000: =IF(OR(D2000="",E2000=""),"",IFERROR(D2000*INDEX(UnidadesFactor,MATCH(E2000,Unidades,0)),"")) | H2000: =IF(I2000<>"OK","",IF(G2000=0,"",F2000/G2000)) | I2000: =IF(B2000="","",IF(ISNA(MATCH(B2000,ListaInsumos,0)),"Insumo no está en Insumos",IF(OR(D2000="",E2000="",F2000=""),"Faltan datos",IF(INDEX(UnidadesBase,MATCH(E2000,Unidades,0))<>INDEX(InsBase,MATCH(B2000,ListaInsumos,0)),"Unidad incompatible",IF(A2000="","Falta fecha","OK")))))

Sheet Recetas
A1: Recetas (ingredientes por tanda)
A2: Una fila por ingrediente. Anotá la cantidad que usás en UNA tanda de la receta. El rendimiento de la tanda se carga en la hoja Costo por Receta.
A4: Receta | B4: Insumo | C4: Cantidad | D4: Unidad | E4: Cantidad en unidad base | F4: Costo por unidad base ($) | G4: Costo en la receta ($) | H4: Control | I4: Notas
A5: Cookies Chips de Chocolate | B5: Garbanzos | D5: g | E5: =IF(OR(C5="",D5=""),"",IFERROR(C5*INDEX(UnidadesFactor,MATCH(D5,Unidades,0)),"")) | F5: =IF(B5="","",IFERROR(INDEX(InsCosto,MATCH(B5,ListaInsumos,0)),"")) | G5: =IF(AND(A5="",B5=""),"",IF(H5="OK",E5*F5,0)) -> 0 | H5: =IF(AND(A5="",B5=""),"",IF(ISNA(MATCH(B5,ListaInsumos,0)),"Insumo no está en Insumos",IF(C5="","Falta cantidad",IF(IFERROR(INDEX(UnidadesBase,MATCH(D5,Unidades,0)),"")<>INDEX(InsBase,MATCH(B5,ListaInsumos,0)),"Unidad incompatible",IF(F5="","Insumo sin compras","OK"))))) -> Falta cantidad
A6: Cookies Chips de Chocolate | B6: Azúcar de coco | D6: g | E6: =IF(OR(C6="",D6=""),"",IFERROR(C6*INDEX(UnidadesFactor,MATCH(D6,Unidades,0)),"")) | F6: =IF(B6="","",IFERROR(INDEX(InsCosto,MATCH(B6,ListaInsumos,0)),"")) | G6: =IF(AND(A6="",B6=""),"",IF(H6="OK",E6*F6,0)) -> 0 | H6: =IF(AND(A6="",B6=""),"",IF(ISNA(MATCH(B6,ListaInsumos,0)),"Insumo no está en Insumos",IF(C6="","Falta cantidad",IF(IFERROR(INDEX(UnidadesBase,MATCH(D6,Unidades,0)),"")<>INDEX(InsBase,MATCH(B6,ListaInsumos,0)),"Unidad incompatible",IF(F6="","Insumo sin compras","OK"))))) -> Falta cantidad
A7: Cookies Chips de Chocolate | B7: Extracto de vainilla | D7: ml | E7: =IF(OR(C7="",D7=""),"",IFERROR(C7*INDEX(UnidadesFactor,MATCH(D7,Unidades,0)),"")) | F7: =IF(B7="","",IFERROR(INDEX(InsCosto,MATCH(B7,ListaInsumos,0)),"")) | G7: =IF(AND(A7="",B7=""),"",IF(H7="OK",E7*F7,0)) -> 0 | H7: =IF(AND(A7="",B7=""),"",IF(ISNA(MATCH(B7,ListaInsumos,0)),"Insumo no está en Insumos",IF(C7="","Falta cantidad",IF(IFERROR(INDEX(UnidadesBase,MATCH(D7,Unidades,0)),"")<>INDEX(InsBase,MATCH(B7,ListaInsumos,0)),"Unidad incompatible",IF(F7="","Insumo sin compras","OK"))))) -> Falta cantidad
A8: Cookies Chips de Chocolate | B8: Polvo de hornear | D8: g | E8: =IF(OR(C8="",D8=""),"",IFERROR(C8*INDEX(UnidadesFactor,MATCH(D8,Unidades,0)),"")) | F8: =IF(B8="","",IFERROR(INDEX(InsCosto,MATCH(B8,ListaInsumos,0)),"")) | G8: =IF(AND(A8="",B8=""),"",IF(H8="OK",E8*F8,0)) -> 0 | H8: =IF(AND(A8="",B8=""),"",IF(ISNA(MATCH(B8,ListaInsumos,0)),"Insumo no está en Insumos",IF(C8="","Falta cantidad",IF(IFERROR(INDEX(UnidadesBase,MATCH(D8,Unidades,0)),"")<>INDEX(InsBase,MATCH(B8,ListaInsumos,0)),"Unidad incompatible",IF(F8="","Insumo sin compras","OK"))))) -> Falta cantidad
A9: Cookies Chips de Chocolate | B9: Goma xántica | D9: g | E9: =IF(OR(C9="",D9=""),"",IFERROR(C9*INDEX(UnidadesFactor,MATCH(D9,Unidades,0)),"")) | F9: =IF(B9="","",IFERROR(INDEX(InsCosto,MATCH(B9,ListaInsumos,0)),"")) -> 60 | G9: =IF(AND(A9="",B9=""),"",IF(H9="OK",E9*F9,0)) -> 0 | H9: =IF(AND(A9="",B9=""),"",IF(ISNA(MATCH(B9,ListaInsumos,0)),"Insumo no está en Insumos",IF(C9="","Falta cantidad",IF(IFERROR(INDEX(UnidadesBase,MATCH(D9,Unidades,0)),"")<>INDEX(InsBase,MATCH(B9,ListaInsumos,0)),"Unidad incompatible",IF(F9="","Insumo sin compras","OK"))))) -> Falta cantidad
A10: Cookies Chips de Chocolate | B10: Chocolate 70% sin azúcar | D10: g | E10: =IF(OR(C10="",D10=""),"",IFERROR(C10*INDEX(UnidadesFactor,MATCH(D10,Unidades,0)),"")) | F10: =IF(B10="","",IFERROR(INDEX(InsCosto,MATCH(B10,ListaInsumos,0)),"")) | G10: =IF(AND(A10="",B10=""),"",IF(H10="OK",E10*F10,0)) -> 0 | H10: =IF(AND(A10="",B10=""),"",IF(ISNA(MATCH(B10,ListaInsumos,0)),"Insumo no está en Insumos",IF(C10="","Falta cantidad",IF(IFERROR(INDEX(UnidadesBase,MATCH(D10,Unidades,0)),"")<>INDEX(InsBase,MATCH(B10,ListaInsumos,0)),"Unidad incompatible",IF(F10="","Insumo sin compras","OK"))))) -> Falta cantidad
A11: Cookies Chips de Chocolate | B11: Sal marina | D11: g | E11: =IF(OR(C11="",D11=""),"",IFERROR(C11*INDEX(UnidadesFactor,MATCH(D11,Unidades,0)),"")) | F11: =IF(B11="","",IFERROR(INDEX(InsCosto,MATCH(B11,ListaInsumos,0)),"")) -> 5 | G11: =IF(AND(A11="",B11=""),"",IF(H11="OK",E11*F11,0)) -> 0 | H11: =IF(AND(A11="",B11=""),"",IF(ISNA(MATCH(B11,ListaInsumos,0)),"Insumo no está en Insumos",IF(C11="","Falta cantidad",IF(IFERROR(INDEX(UnidadesBase,MATCH(D11,Unidades,0)),"")<>INDEX(InsBase,MATCH(B11,ListaInsumos,0)),"Unidad incompatible",IF(F11="","Insumo sin compras","OK"))))) -> Falta cantidad
A12: Pan de Molde con Trigo Sarraceno | B12: Trigo sarraceno | D12: g | E12: =IF(OR(C12="",D12=""),"",IFERROR(C12*INDEX(UnidadesFactor,MATCH(D12,Unidades,0)),"")) | F12: =IF(B12="","",IFERROR(INDEX(InsCosto,MATCH(B12,ListaInsumos,0)),"")) | G12: =IF(AND(A12="",B12=""),"",IF(H12="OK",E12*F12,0)) -> 0 | H12: =IF(AND(A12="",B12=""),"",IF(ISNA(MATCH(B12,ListaInsumos,0)),"Insumo no está en Insumos",IF(C12="","Falta cantidad",IF(IFERROR(INDEX(UnidadesBase,MATCH(D12,Unidades,0)),"")<>INDEX(InsBase,MATCH(B12,ListaInsumos,0)),"Unidad incompatible",IF(F12="","Insumo sin compras","OK"))))) -> Falta cantidad
A13: Pan de Molde con Trigo Sarraceno | B13: Harina de sorgo | D13: g | E13: =IF(OR(C13="",D13=""),"",IFERROR(C13*INDEX(UnidadesFactor,MATCH(D13,Unidades,0)),"")) | F13: =IF(B13="","",IFERROR(INDEX(InsCosto,MATCH(B13,ListaInsumos,0)),"")) | G13: =IF(AND(A13="",B13=""),"",IF(H13="OK",E13*F13,0)) -> 0 | H13: =IF(AND(A13="",B13=""),"",IF(ISNA(MATCH(B13,ListaInsumos,0)),"Insumo no está en Insumos",IF(C13="","Falta cantidad",IF(IFERROR(INDEX(UnidadesBase,MATCH(D13,Unidades,0)),"")<>INDEX(InsBase,MATCH(B13,ListaInsumos,0)),"Unidad incompatible",IF(F13="","Insumo sin compras","OK"))))) -> Falta cantidad
A14: Pan de Molde con Trigo Sarraceno | B14: Harina de lino | D14: g | E14: =IF(OR(C14="",D14=""),"",IFERROR(C14*INDEX(UnidadesFactor,MATCH(D14,Unidades,0)),"")) | F14: =IF(B14="","",IFERROR(INDEX(InsCosto,MATCH(B14,ListaInsumos,0)),"")) | G14: =IF(AND(A14="",B14=""),"",IF(H14="OK",E14*F14,0)) -> 0 | H14: =IF(AND(A14="",B14=""),"",IF(ISNA(MATCH(B14,ListaInsumos,0)),"Insumo no está en Insumos",IF(C14="","Falta cantidad",IF(IFERROR(INDEX(UnidadesBase,MATCH(D14,Unidades,0)),"")<>INDEX(InsBase,MATCH(B14,ListaInsumos,0)),"Unidad incompatible",IF(F14="","Insumo sin compras","OK"))))) -> Falta cantidad
A15: Pan de Molde con Trigo Sarraceno | B15: Harina de arroz | D15: g | E15: =IF(OR(C15="",D15=""),"",IFERROR(C15*INDEX(UnidadesFactor,MATCH(D15,Unidades,0)),"")) | F15: =IF(B15="","",IFERROR(INDEX(InsCosto,MATCH(B15,ListaInsumos,0)),"")) -> 2.8 | G15: =IF(AND(A15="",B15=""),"",IF(H15="OK",E15*F15,0)) -> 0 | H15: =IF(AND(A15="",B15=""),"",IF(ISNA(MATCH(B15,ListaInsumos,0)),"Insumo no está en Insumos",IF(C15="","Falta cantidad",IF(IFERROR(INDEX(UnidadesBase,MATCH(D15,Unidades,0)),"")<>INDEX(InsBase,MATCH(B15,ListaInsumos,0)),"Unidad incompatible",IF(F15="","Insumo sin compras","OK"))))) -> Falta cantidad
A16: Pan de Molde con Trigo Sarraceno | B16: Almidón de mandioca | D16: g | E16: =IF(OR(C16="",D16=""),"",IFERROR(C16*INDEX(UnidadesFactor,MATCH(D16,Unidades,0)),"")) | F16: =IF(B16="","",IFERROR(INDEX(InsCosto,MATCH(B16,ListaInsumos,0)),"")) -> 3.5 | G16: =IF(AND(A16="",B16=""),"",IF(H16="OK",E16*F16,0)) -> 0 | H16: =IF(AND(A16="",B16=""),"",IF(ISNA(MATCH(B16,ListaInsumos,0)),"Insumo no está en Insumos",IF(C16="","Falta cantidad",IF(IFERROR(INDEX(UnidadesBase,MATCH(D16,Unidades,0)),"")<>INDEX(InsBase,MATCH(B16,ListaInsumos,0)),"Unidad incompatible",IF(F16="","Insumo sin compras","OK"))))) -> Falta cantidad
... A27: Tablitas de Trigo Sarraceno y Semillas | B27: Semillas (mix) | D27: g | E27: =IF(OR(C27="",D27=""),"",IFERROR(C27*INDEX(UnidadesFactor,MATCH(D27,Unidades,0)),"")) | F27: =IF(B27="","",IFERROR(INDEX(InsCosto,MATCH(B27,ListaInsumos,0)),"")) | G27: =IF(AND(A27="",B27=""),"",IF(H27="OK",E27*F27,0)) -> 0 | H27: =IF(AND(A27="",B27=""),"",IF(ISNA(MATCH(B27,ListaInsumos,0)),"Insumo no está en Insumos",IF(C27="","Falta cantidad",IF(IFERROR(INDEX(UnidadesBase,MATCH(D27,Unidades,0)),"")<>INDEX(InsBase,MATCH(B27,ListaInsumos,0)),"Unidad incompatible",IF(F27="","Insumo sin compras","OK"))))) -> Falta cantidad
A28: Galletas Marineras | B28: Almidón de maíz | C28: 200 | D28: g | E28: =IF(OR(C28="",D28=""),"",IFERROR(C28*INDEX(UnidadesFactor,MATCH(D28,Unidades,0)),"")) -> 200 | F28: =IF(B28="","",IFERROR(INDEX(InsCosto,MATCH(B28,ListaInsumos,0)),"")) -> 3 | G28: =IF(AND(A28="",B28=""),"",IF(H28="OK",E28*F28,0)) -> 600 | H28: =IF(AND(A28="",B28=""),"",IF(ISNA(MATCH(B28,ListaInsumos,0)),"Insumo no está en Insumos",IF(C28="","Falta cantidad",IF(IFERROR(INDEX(UnidadesBase,MATCH(D28,Unidades,0)),"")<>INDEX(InsBase,MATCH(B28,ListaInsumos,0)),"Unidad incompatible",IF(F28="","Insumo sin compras","OK"))))) -> OK | I28: EJEMPLO: reemplazar por datos reales
A29: Galletas Marineras | B29: Harina de arroz | C29: 150 | D29: g | E29: =IF(OR(C29="",D29=""),"",IFERROR(C29*INDEX(UnidadesFactor,MATCH(D29,Unidades,0)),"")) -> 150 | F29: =IF(B29="","",IFERROR(INDEX(InsCosto,MATCH(B29,ListaInsumos,0)),"")) -> 2.8 | G29: =IF(AND(A29="",B29=""),"",IF(H29="OK",E29*F29,0)) -> 420 | H29: =IF(AND(A29="",B29=""),"",IF(ISNA(MATCH(B29,ListaInsumos,0)),"Insumo no está en Insumos",IF(C29="","Falta cantidad",IF(IFERROR(INDEX(UnidadesBase,MATCH(D29,Unidades,0)),"")<>INDEX(InsBase,MATCH(B29,ListaInsumos,0)),"Unidad incompatible",IF(F29="","Insumo sin compras","OK"))))) -> OK | I29: EJEMPLO: reemplazar por datos reales
A30: Galletas Marineras | B30: Almidón de mandioca | C30: 100 | D30: g | E30: =IF(OR(C30="",D30=""),"",IFERROR(C30*INDEX(UnidadesFactor,MATCH(D30,Unidades,0)),"")) -> 100 | F30: =IF(B30="","",IFERROR(INDEX(InsCosto,MATCH(B30,ListaInsumos,0)),"")) -> 3.5 | G30: =IF(AND(A30="",B30=""),"",IF(H30="OK",E30*F30,0)) -> 350 | H30: =IF(AND(A30="",B30=""),"",IF(ISNA(MATCH(B30,ListaInsumos,0)),"Insumo no está en Insumos",IF(C30="","Falta cantidad",IF(IFERROR(INDEX(UnidadesBase,MATCH(D30,Unidades,0)),"")<>INDEX(InsBase,MATCH(B30,ListaInsumos,0)),"Unidad incompatible",IF(F30="","Insumo sin compras","OK"))))) -> OK | I30: EJEMPLO: reemplazar por datos reales
A31: Galletas Marineras | B31: Aceite de oliva | C31: 60 | D31: ml | E31: =IF(OR(C31="",D31=""),"",IFERROR(C31*INDEX(UnidadesFactor,MATCH(D31,Unidades,0)),"")) -> 60 | F31: =IF(B31="","",IFERROR(INDEX(InsCosto,MATCH(B31,ListaInsumos,0)),"")) -> 18 | G31: =IF(AND(A31="",B31=""),"",IF(H31="OK",E31*F31,0)) -> 1080 | H31: =IF(AND(A31="",B31=""),"",IF(ISNA(MATCH(B31,ListaInsumos,0)),"Insumo no está en Insumos",IF(C31="","Falta cantidad",IF(IFERROR(INDEX(UnidadesBase,MATCH(D31,Unidades,0)),"")<>INDEX(InsBase,MATCH(B31,ListaInsumos,0)),"Unidad incompatible",IF(F31="","Insumo sin compras","OK"))))) -> OK | I31: EJEMPLO: reemplazar por datos reales
A32: Galletas Marineras | B32: Sal marina | C32: 5 | D32: g | E32: =IF(OR(C32="",D32=""),"",IFERROR(C32*INDEX(UnidadesFactor,MATCH(D32,Unidades,0)),"")) -> 5 | F32: =IF(B32="","",IFERROR(INDEX(InsCosto,MATCH(B32,ListaInsumos,0)),"")) -> 5 | G32: =IF(AND(A32="",B32=""),"",IF(H32="OK",E32*F32,0)) -> 25 | H32: =IF(AND(A32="",B32=""),"",IF(ISNA(MATCH(B32,ListaInsumos,0)),"Insumo no está en Insumos",IF(C32="","Falta cantidad",IF(IFERROR(INDEX(UnidadesBase,MATCH(D32,Unidades,0)),"")<>INDEX(InsBase,MATCH(B32,ListaInsumos,0)),"Unidad incompatible",IF(F32="","Insumo sin compras","OK"))))) -> OK | I32: EJEMPLO: reemplazar por datos reales
A33: Galletas Marineras | B33: Goma xántica | C33: 5 | D33: g | E33: =IF(OR(C33="",D33=""),"",IFERROR(C33*INDEX(UnidadesFactor,MATCH(D33,Unidades,0)),"")) -> 5 | F33: =IF(B33="","",IFERROR(INDEX(InsCosto,MATCH(B33,ListaInsumos,0)),"")) -> 60 | G33: =IF(AND(A33="",B33=""),"",IF(H33="OK",E33*F33,0)) -> 300 | H33: =IF(AND(A33="",B33=""),"",IF(ISNA(MATCH(B33,ListaInsumos,0)),"Insumo no está en Insumos",IF(C33="","Falta cantidad",IF(IFERROR(INDEX(UnidadesBase,MATCH(D33,Unidades,0)),"")<>INDEX(InsBase,MATCH(B33,ListaInsumos,0)),"Unidad incompatible",IF(F33="","Insumo sin compras","OK"))))) -> OK | I33: EJEMPLO: reemplazar por datos reales
A34: Galletas Marineras | B34: Polvo leudante | C34: 8 | D34: g | E34: =IF(OR(C34="",D34=""),"",IFERROR(C34*INDEX(UnidadesFactor,MATCH(D34,Unidades,0)),"")) -> 8 | F34: =IF(B34="","",IFERROR(INDEX(InsCosto,MATCH(B34,ListaInsumos,0)),"")) -> 15 | G34: =IF(AND(A34="",B34=""),"",IF(H34="OK",E34*F34,0)) -> 120 | H34: =IF(AND(A34="",B34=""),"",IF(ISNA(MATCH(B34,ListaInsumos,0)),"Insumo no está en Insumos",IF(C34="","Falta cantidad",IF(IFERROR(INDEX(UnidadesBase,MATCH(D34,Unidades,0)),"")<>INDEX(InsBase,MATCH(B34,ListaInsumos,0)),"Unidad incompatible",IF(F34="","Insumo sin compras","OK"))))) -> OK | I34: EJEMPLO: reemplazar por datos reales
A35: Crakers de Mijo y Cebolla | B35: Mijo | D35: g | E35: =IF(OR(C35="",D35=""),"",IFERROR(C35*INDEX(UnidadesFactor,MATCH(D35,Unidades,0)),"")) | F35: =IF(B35="","",IFERROR(INDEX(InsCosto,MATCH(B35,ListaInsumos,0)),"")) | G35: =IF(AND(A35="",B35=""),"",IF(H35="OK",E35*F35,0)) -> 0 | H35: =IF(AND(A35="",B35=""),"",IF(ISNA(MATCH(B35,ListaInsumos,0)),"Insumo no está en Insumos",IF(C35="","Falta cantidad",IF(IFERROR(INDEX(UnidadesBase,MATCH(D35,Unidades,0)),"")<>INDEX(InsBase,MATCH(B35,ListaInsumos,0)),"Unidad incompatible",IF(F35="","Insumo sin compras","OK"))))) -> Falta cantidad
A36: Crakers de Mijo y Cebolla | B36: Cebolla en polvo | D36: g | E36: =IF(OR(C36="",D36=""),"",IFERROR(C36*INDEX(UnidadesFactor,MATCH(D36,Unidades,0)),"")) | F36: =IF(B36="","",IFERROR(INDEX(InsCosto,MATCH(B36,ListaInsumos,0)),"")) | G36: =IF(AND(A36="",B36=""),"",IF(H36="OK",E36*F36,0)) -> 0 | H36: =IF(AND(A36="",B36=""),"",IF(ISNA(MATCH(B36,ListaInsumos,0)),"Insumo no está en Insumos",IF(C36="","Falta cantidad",IF(IFERROR(INDEX(UnidadesBase,MATCH(D36,Unidades,0)),"")<>INDEX(InsBase,MATCH(B36,ListaInsumos,0)),"Unidad incompatible",IF(F36="","Insumo sin compras","OK"))))) -> Falta cantidad
A37: Crakers de Mijo y Cebolla | B37: Pimienta negra | D37: g | E37: =IF(OR(C37="",D37=""),"",IFERROR(C37*INDEX(UnidadesFactor,MATCH(D37,Unidades,0)),"")) | F37: =IF(B37="","",IFERROR(INDEX(InsCosto,MATCH(B37,ListaInsumos,0)),"")) | G37: =IF(AND(A37="",B37=""),"",IF(H37="OK",E37*F37,0)) -> 0 | H37: =IF(AND(A37="",B37=""),"",IF(ISNA(MATCH(B37,ListaInsumos,0)),"Insumo no está en Insumos",IF(C37="","Falta cantidad",IF(IFERROR(INDEX(UnidadesBase,MATCH(D37,Unidades,0)),"")<>INDEX(InsBase,MATCH(B37,ListaInsumos,0)),"Unidad incompatible",IF(F37="","Insumo sin compras","OK"))))) -> Falta cantidad
A38: Crakers de Mijo y Cebolla | B38: Cúrcuma | D38: g | E38: =IF(OR(C38="",D38=""),"",IFERROR(C38*INDEX(UnidadesFactor,MATCH(D38,Unidades,0)),"")) | F38: =IF(B38="","",IFERROR(INDEX(InsCosto,MATCH(B38,ListaInsumos,0)),"")) | G38: =IF(AND(A38="",B38=""),"",IF(H38="OK",E38*F38,0)) -> 0 | H38: =IF(AND(A38="",B38=""),"",IF(ISNA(MATCH(B38,ListaInsumos,0)),"Insumo no está en Insumos",IF(C38="","Falta cantidad",IF(IFERROR(INDEX(UnidadesBase,MATCH(D38,Unidades,0)),"")<>INDEX(InsBase,MATCH(B38,ListaInsumos,0)),"Unidad incompatible",IF(F38="","Insumo sin compras","OK"))))) -> Falta cantidad
A39: Crakers de Mijo y Cebolla | B39: Aceite de oliva | D39: ml | E39: =IF(OR(C39="",D39=""),"",IFERROR(C39*INDEX(UnidadesFactor,MATCH(D39,Unidades,0)),"")) | F39: =IF(B39="","",IFERROR(INDEX(InsCosto,MATCH(B39,ListaInsumos,0)),"")) -> 18 | G39: =IF(AND(A39="",B39=""),"",IF(H39="OK",E39*F39,0)) -> 0 | H39: =IF(AND(A39="",B39=""),"",IF(ISNA(MATCH(B39,ListaInsumos,0)),"Insumo no está en Insumos",IF(C39="","Falta cantidad",IF(IFERROR(INDEX(UnidadesBase,MATCH(D39,Unidades,0)),"")<>INDEX(InsBase,MATCH(B39,ListaInsumos,0)),"Unidad incompatible",IF(F39="","Insumo sin compras","OK"))))) -> Falta cantidad
A40: Crakers de Mijo y Cebolla | B40: Sal marina | D40: g | E40: =IF(OR(C40="",D40=""),"",IFERROR(C40*INDEX(UnidadesFactor,MATCH(D40,Unidades,0)),"")) | F40: =IF(B40="","",IFERROR(INDEX(InsCosto,MATCH(B40,ListaInsumos,0)),"")) -> 5 | G40: =IF(AND(A40="",B40=""),"",IF(H40="OK",E40*F40,0)) -> 0 | H40: =IF(AND(A40="",B40=""),"",IF(ISNA(MATCH(B40,ListaInsumos,0)),"Insumo no está en Insumos",IF(C40="","Falta cantidad",IF(IFERROR(INDEX(UnidadesBase,MATCH(D40,Unidades,0)),"")<>INDEX(InsBase,MATCH(B40,ListaInsumos,0)),"Unidad incompatible",IF(F40="","Insumo sin compras","OK"))))) -> Falta cantidad
A41: Crakers de Mijo y Cebolla | B41: Goma xántica | D41: g | E41: =IF(OR(C41="",D41=""),"",IFERROR(C41*INDEX(UnidadesFactor,MATCH(D41,Unidades,0)),"")) | F41: =IF(B41="","",IFERROR(INDEX(InsCosto,MATCH(B41,ListaInsumos,0)),"")) -> 60 | G41: =IF(AND(A41="",B41=""),"",IF(H41="OK",E41*F41,0)) -> 0 | H41: =IF(AND(A41="",B41=""),"",IF(ISNA(MATCH(B41,ListaInsumos,0)),"Insumo no está en Insumos",IF(C41="","Falta cantidad",IF(IFERROR(INDEX(UnidadesBase,MATCH(D41,Unidades,0)),"")<>INDEX(InsBase,MATCH(B41,ListaInsumos,0)),"Unidad incompatible",IF(F41="","Insumo sin compras","OK"))))) -> Falta cantidad
A42: Palitos de Batata y Romero | B42: Batata | D42: g | E42: =IF(OR(C42="",D42=""),"",IFERROR(C42*INDEX(UnidadesFactor,MATCH(D42,Unidades,0)),"")) | F42: =IF(B42="","",IFERROR(INDEX(InsCosto,MATCH(B42,ListaInsumos,0)),"")) | G42: =IF(AND(A42="",B42=""),"",IF(H42="OK",E42*F42,0)) -> 0 | H42: =IF(AND(A42="",B42=""),"",IF(ISNA(MATCH(B42,ListaInsumos,0)),"Insumo no está en Insumos",IF(C42="","Falta cantidad",IF(IFERROR(INDEX(UnidadesBase,MATCH(D42,Unidades,0)),"")<>INDEX(InsBase,MATCH(B42,ListaInsumos,0)),"Unidad incompatible",IF(F42="","Insumo sin compras","OK"))))) -> Falta cantidad
A43: Palitos de Batata y Romero | B43: Romero | D43: g | E43: =IF(OR(C43="",D43=""),"",IFERROR(C43*INDEX(UnidadesFactor,MATCH(D43,Unidades,0)),"")) | F43: =IF(B43="","",IFERROR(INDEX(InsCosto,MATCH(B43,ListaInsumos,0)),"")) | G43: =IF(AND(A43="",B43=""),"",IF(H43="OK",E43*F43,0)) -> 0 | H43: =IF(AND(A43="",B43=""),"",IF(ISNA(MATCH(B43,ListaInsumos,0)),"Insumo no está en Insumos",IF(C43="","Falta cantidad",IF(IFERROR(INDEX(UnidadesBase,MATCH(D43,Unidades,0)),"")<>INDEX(InsBase,MATCH(B43,ListaInsumos,0)),"Unidad incompatible",IF(F43="","Insumo sin compras","OK"))))) -> Falta cantidad
A44: Palitos de Batata y Romero | B44: Aceite de oliva | D44: ml | E44: =IF(OR(C44="",D44=""),"",IFERROR(C44*INDEX(UnidadesFactor,MATCH(D44,Unidades,0)),"")) | F44: =IF(B44="","",IFERROR(INDEX(InsCosto,MATCH(B44,ListaInsumos,0)),"")) -> 18 | G44: =IF(AND(A44="",B44=""),"",IF(H44="OK",E44*F44,0)) -> 0 | H44: =IF(AND(A44="",B44=""),"",IF(ISNA(MATCH(B44,ListaInsumos,0)),"Insumo no está en Insumos",IF(C44="","Falta cantidad",IF(IFERROR(INDEX(UnidadesBase,MATCH(D44,Unidades,0)),"")<>INDEX(InsBase,MATCH(B44,ListaInsumos,0)),"Unidad incompatible",IF(F44="","Insumo sin compras","OK"))))) -> Falta cantidad
A45: Palitos de Batata y Romero | B45: Sal marina | D45: g | E45: =IF(OR(C45="",D45=""),"",IFERROR(C45*INDEX(UnidadesFactor,MATCH(D45,Unidades,0)),"")) | F45: =IF(B45="","",IFERROR(INDEX(InsCosto,MATCH(B45,ListaInsumos,0)),"")) -> 5 | G45: =IF(AND(A45="",B45=""),"",IF(H45="OK",E45*F45,0)) -> 0 | H45: =IF(AND(A45="",B45=""),"",IF(ISNA(MATCH(B45,ListaInsumos,0)),"Insumo no está en Insumos",IF(C45="","Falta cantidad",IF(IFERROR(INDEX(UnidadesBase,MATCH(D45,Unidades,0)),"")<>INDEX(InsBase,MATCH(B45,ListaInsumos,0)),"Unidad incompatible",IF(F45="","Insumo sin compras","OK"))))) -> Falta cantidad
A46: Palitos de Batata y Romero | B46: Goma xántica | D46: g | E46: =IF(OR(C46="",D46=""),"",IFERROR(C46*INDEX(UnidadesFactor,MATCH(D46,Unidades,0)),"")) | F46: =IF(B46="","",IFERROR(INDEX(InsCosto,MATCH(B46,ListaInsumos,0)),"")) -> 60 | G46: =IF(AND(A46="",B46=""),"",IF(H46="OK",E46*F46,0)) -> 0 | H46: =IF(AND(A46="",B46=""),"",IF(ISNA(MATCH(B46,ListaInsumos,0)),"Insumo no está en Insumos",IF(C46="","Falta cantidad",IF(IFERROR(INDEX(UnidadesBase,MATCH(D46,Unidades,0)),"")<>INDEX(InsBase,MATCH(B46,ListaInsumos,0)),"Unidad incompatible",IF(F46="","Insumo sin compras","OK"))))) -> Falta cantidad
... A84: Bastoncitos de Zanahoria y Remolacha | B84: Nuez moscada | D84: g | E84: =IF(OR(C84="",D84=""),"",IFERROR(C84*INDEX(UnidadesFactor,MATCH(D84,Unidades,0)),"")) | F84: =IF(B84="","",IFERROR(INDEX(InsCosto,MATCH(B84,ListaInsumos,0)),"")) | G84: =IF(AND(A84="",B84=""),"",IF(H84="OK",E84*F84,0)) -> 0 | H84: =IF(AND(A84="",B84=""),"",IF(ISNA(MATCH(B84,ListaInsumos,0)),"Insumo no está en Insumos",IF(C84="","Falta cantidad",IF(IFERROR(INDEX(UnidadesBase,MATCH(D84,Unidades,0)),"")<>INDEX(InsBase,MATCH(B84,ListaInsumos,0)),"Unidad incompatible",IF(F84="","Insumo sin compras","OK"))))) -> Falta cantidad
A85: Azúcar de coco fraccionada | B85: Azúcar de coco | C85: 200 | D85: g | E85: =IF(OR(C85="",D85=""),"",IFERROR(C85*INDEX(UnidadesFactor,MATCH(D85,Unidades,0)),"")) -> 200 | F85: =IF(B85="","",IFERROR(INDEX(InsCosto,MATCH(B85,ListaInsumos,0)),"")) | G85: =IF(AND(A85="",B85=""),"",IF(H85="OK",E85*F85,0)) -> 0 | H85: =IF(AND(A85="",B85=""),"",IF(ISNA(MATCH(B85,ListaInsumos,0)),"Insumo no está en Insumos",IF(C85="","Falta cantidad",IF(IFERROR(INDEX(UnidadesBase,MATCH(D85,Unidades,0)),"")<>INDEX(InsBase,MATCH(B85,ListaInsumos,0)),"Unidad incompatible",IF(F85="","Insumo sin compras","OK"))))) -> Insumo sin compras
A86: Mermelada (reventa) | B86: Mermelada Lo Artesanal 200 g | C86: 1 | D86: unidad | E86: =IF(OR(C86="",D86=""),"",IFERROR(C86*INDEX(UnidadesFactor,MATCH(D86,Unidades,0)),"")) -> 1 | F86: =IF(B86="","",IFERROR(INDEX(InsCosto,MATCH(B86,ListaInsumos,0)),"")) | G86: =IF(AND(A86="",B86=""),"",IF(H86="OK",E86*F86,0)) -> 0 | H86: =IF(AND(A86="",B86=""),"",IF(ISNA(MATCH(B86,ListaInsumos,0)),"Insumo no está en Insumos",IF(C86="","Falta cantidad",IF(IFERROR(INDEX(UnidadesBase,MATCH(D86,Unidades,0)),"")<>INDEX(InsBase,MATCH(B86,ListaInsumos,0)),"Unidad incompatible",IF(F86="","Insumo sin compras","OK"))))) -> Insumo sin compras
A87: Berenjenas Húngaras (reventa) | B87: Berenjenas Húngaras 150 g | C87: 1 | D87: unidad | E87: =IF(OR(C87="",D87=""),"",IFERROR(C87*INDEX(UnidadesFactor,MATCH(D87,Unidades,0)),"")) -> 1 | F87: =IF(B87="","",IFERROR(INDEX(InsCosto,MATCH(B87,ListaInsumos,0)),"")) | G87: =IF(AND(A87="",B87=""),"",IF(H87="OK",E87*F87,0)) -> 0 | H87: =IF(AND(A87="",B87=""),"",IF(ISNA(MATCH(B87,ListaInsumos,0)),"Insumo no está en Insumos",IF(C87="","Falta cantidad",IF(IFERROR(INDEX(UnidadesBase,MATCH(D87,Unidades,0)),"")<>INDEX(InsBase,MATCH(B87,ListaInsumos,0)),"Unidad incompatible",IF(F87="","Insumo sin compras","OK"))))) -> Insumo sin compras
A88: Aceitunas Condimentadas (reventa) | B88: Aceitunas Condimentadas 300 g | C88: 1 | D88: unidad | E88: =IF(OR(C88="",D88=""),"",IFERROR(C88*INDEX(UnidadesFactor,MATCH(D88,Unidades,0)),"")) -> 1 | F88: =IF(B88="","",IFERROR(INDEX(InsCosto,MATCH(B88,ListaInsumos,0)),"")) | G88: =IF(AND(A88="",B88=""),"",IF(H88="OK",E88*F88,0)) -> 0 | H88: =IF(AND(A88="",B88=""),"",IF(ISNA(MATCH(B88,ListaInsumos,0)),"Insumo no está en Insumos",IF(C88="","Falta cantidad",IF(IFERROR(INDEX(UnidadesBase,MATCH(D88,Unidades,0)),"")<>INDEX(InsBase,MATCH(B88,ListaInsumos,0)),"Unidad incompatible",IF(F88="","Insumo sin compras","OK"))))) -> Insumo sin compras
...

Sheet Costo por Receta
A1: Costo por receta
A2: Cargá cuánto producto terminado sale de cada tanda (pesalo DESPUÉS de hornear/deshidratar: pierde agua). Así se obtiene el costo por gramo real.
A4: Receta | B4: Rendimiento de la tanda (producto terminado) | C4: Unidad del rendimiento | D4: Costo total de ingredientes ($) | E4: Costo por gramo / unidad ($) | F4: Costo por kg ($) | G4: Ingredientes cargados | H4: Estado
